Workbook
Name __bookmark_1: '[3]9.23库存'!#REF!
Name __lg1: #REF!
Name __lg2: #REF!
Name _111111: #REF!
Name _lg1: #REF!
Name _lg2: #REF!
Name 【9月】: #REF!
Name 【9月】活动规划: #REF!
Name ·: #REF!
Name ·111: OFFSET(#REF!,0,1,#REF!,1)
Name a: #REF!
Name AA: #REF!
Name aaaa: #REF!
Name AAAAAAAAAA: [15]Template!#REF!
Name Action: [16]OR!$CJ$417:$CJ$436
Name Actual: [17]微淘双11规划!A$5=MEDIAN([17]微淘双11规划!A$5,[17]微淘双11规划!$F1,[17]微淘双11规划!$G1)*([17]微淘双11规划!$F1<>0)*([17]微淘双11规划!$G1<>0)
Name ACTUAL_PLAN: [18]RANGES!$F$5:$F$6
Name Advance: [17]微淘双11规划!A$5=([17]微淘双11规划!$F1<[17]微淘双11规划!$D1)*MEDIAN([17]微淘双11规划!A$5,[17]微淘双11规划!$F1,([17]微淘双11规划!$D1-1))*([17]微淘双11规划!$F1<>0)*([17]微淘双11规划!$G1<>0)
Name again: #REF!
Name Agency: #REF!
Name agency1: #REF!
Name agency2: #REF!
Name AgencyCommission: #REF!
Name alex: #REF!
Name ALL: #REF!
Name app: #REF!
Name asd: [19]Spotplan!#REF!
Name Asiadiscontinued: #REF!
Name ass: #REF!
Name august: #REF!
Name august2: #REF!
Name b: #REF!
Name BaseCost: #REF!
Name BaseRate: [20]Template!#REF!
Name bb: #REF!
Name Beg_Bal: #REF!
Name Benelux: #REF!
Name BillingSource: #REF!
Name BillingSourceList: [21]Lists!$F$1:$F$4
Name BillingSourceList2: [22]Lists!$F$1:$F$4
Name blush: #REF!
Name BNM: #REF!
Name BNMm: #REF!
Name BOM_Options: #REF!
Name BooleanList: [21]Lists!$D$1:$D$2
Name BooleanList2: [22]Lists!$D$1:$D$2
Name Borders: [23]hide!$F$2:$F$3
Name Brand: #REF!
Name brush: #REF!
Name BuyTypeList: [21]Lists!$A$1:$A$6
Name BuyTypeList2: [22]Lists!$A$1:$A$6
Name BYD: #REF!
Name candy: #REF!
Name cannib: #REF!
Name CCB: #REF!
Name ceca: [25]Sheet1!$A$1:$H$65536
Name Channels: #REF!
Name CN: #REF!
Name code: #REF!
Name code_filter: #REF!

Sheet 目标表
A1: Date | B1: gmv | C1: net | D1: net_units | E1: gmv_units | F1: rrc | G1: uv | H1: cr | I1: aov | J1: atv | K1: buyers | L1: free_traffic | M1: paid_traffic | N1: dtc_social_net | O1: dtc_social_gmv | P1: dtc_social_rrc | Q1: dtc_social_traffic | R1: dtc_organic_net | S1: dtc_organic_gmv | T1: dtc_organic_rrc | U1: dtc_organic_traffic | V1: channel
A2: 45748 | B2: 4237 | C2: 3390 | D2: 1 | E2: 1 | F2: 0.2 | G2: 400 | H2: 0.0025 | I2: 4500 | J2: 4950 | K2: 1 | L2: 400 | M2: 0 | N2: 0 | O2: 0 | P2: 0 | Q2: 0 | R2: 3390 | S2: 4237.5 | T2: 0.2 | U2: 400 | V2: DTC
A3: 45749 | B3: 0 | C3: 0 | D3: 0 | E3: 0 | F3: 0 | G3: 400 | H3: 0 | I3: 0 | J3: 0 | K3: 0 | L3: 400 | M3: 0 | N3: 0 | O3: 0 | P3: 0 | Q3: 0 | R3: 0 | S3: 0 | T3: 0 | U3: 400 | V3: DTC
A4: 45750 | B4: 0 | C4: 0 | D4: 0 | E4: 0 | F4: 0 | G4: 400 | H4: 0 | I4: 0 | J4: 0 | K4: 0 | L4: 400 | M4: 0 | N4: 0 | O4: 0 | P4: 0 | Q4: 0 | R4: 0 | S4: 0 | T4: 0 | U4: 400 | V4: DTC
A5: 45751 | B5: 0 | C5: 0 | D5: 0 | E5: 0 | F5: 0 | G5: 400 | H5: 0 | I5: 0 | J5: 0 | K5: 0 | L5: 400 | M5: 0 | N5: 0 | O5: 0 | P5: 0 | Q5: 0 | R5: 0 | S5: 0 | T5: 0 | U5: 400 | V5: DTC
A6: 45752 | B6: 0 | C6: 0 | D6: 0 | E6: 0 | F6: 0 | G6: 400 | H6: 0 | I6: 0 | J6: 0 | K6: 0 | L6: 400 | M6: 0 | N6: 0 | O6: 0 | P6: 0 | Q6: 0 | R6: 0 | S6: 0 | T6: 0 | U6: 400 | V6: DTC
A7: 45753 | B7: 0 | C7: 0 | D7: 0 | E7: 0 | F7: 0 | G7: 400 | H7: 0 | I7: 0 | J7: 0 | K7: 0 | L7: 400 | M7: 0 | N7: 0 | O7: 0 | P7: 0 | Q7: 0 | R7: 0 | S7: 0 | T7: 0 | U7: 400 | V7: DTC
A8: 45754 | B8: 4237 | C8: 3390 | D8: 1 | E8: 1 | F8: 0.2 | G8: 400 | H8: 0.0025 | I8: 4500 | J8: 4950 | K8: 1 | L8: 400 | M8: 0 | N8: 0 | O8: 0 | P8: 0 | Q8: 0 | R8: 3390 | S8: 4237.5 | T8: 0.2 | U8: 400 | V8: DTC
A9: 45755 | B9: 0 | C9: 0 | D9: 0 | E9: 0 | F9: 0 | G9: 400 | H9: 0 | I9: 0 | J9: 0 | K9: 0 | L9: 400 | M9: 0 | N9: 0 | O9: 0 | P9: 0 | Q9: 0 | R9: 0 | S9: 0 | T9: 0 | U9: 400 | V9: DTC
A10: 45756 | B10: 0 | C10: 0 | D10: 0 | E10: 0 | F10: 0 | G10: 400 | H10: 0 | I10: 0 | J10: 0 | K10: 0 | L10: 400 | M10: 0 | N10: 0 | O10: 0 | P10: 0 | Q10: 0 | R10: 0 | S10: 0 | T10: 0 | U10: 400 | V10: DTC
A11: 45757 | B11: 28027 | C11: 25990 | D11: 6 | E11: 6 | F11: 0.072679045 | G11: 410 | H11: 0.014634146 | I11: 4500 | J11: 4950 | K11: 6 | L11: 400 | M11: 10 | N11: 22600 | O11: 23789.474 | P11: 0.05 | Q11: 10 | R11: 3390 | S11: 4237.5 | T11: 0.2 | U11: 400 | V11: DTC
A12: 45758 | B12: 16132 | C12: 14690 | D12: 3 | E12: 4 | F12: 0.089400922 | G12: 410 | H12: 0.0073170732 | I12: 4500 | J12: 4950 | K12: 3 | L12: 400 | M12: 10 | N12: 11300 | O12: 11894.737 | P12: 0.05 | Q12: 10 | R12: 3390 | S12: 4237.5 | T12: 0.2 | U12: 400 | V12: DTC
A13: 45759 | B13: 11895 | C13: 11300 | D13: 3 | E13: 3 | F13: 0.05 | G13: 410 | H13: 0.0048780488 | I13: 4500 | J13: 4950 | K13: 2 | L13: 400 | M13: 10 | N13: 11300 | O13: 11894.737 | P13: 0.05 | Q13: 10 | R13: 0 | S13: 0 | T13: 0.2 | U13: 400 | V13: DTC
... A226: 45972 | B226: 4211 | C226: 4000 | D226: 1 | E226: 1 | F226: 0.05 | G226: 400 | H226: 0.0025 | I226: 4000 | J226: 4400 | K226: 1 | L226: 400 | M226: 0 | N226: 0 | O226: 0 | P226: 0 | Q226: 0 | R226: 4000 | S226: 4210.5263 | T226: 0.05 | U226: 400 | V226: DTC
A227: 45973 | B227: 0 | C227: 0 | D227: 0 | E227: 0 | F227: 0 | G227: 400 | H227: 0 | I227: 0 | J227: 0 | K227: 0 | L227: 400 | M227: 0 | N227: 0 | O227: 0 | P227: 0 | Q227: 0 | R227: 0 | T227: 0.05 | U227: 400 | V227: DTC
A228: 45974 | B228: 4211 | C228: 4000 | D228: 1 | E228: 1 | F228: 0.05 | G228: 400 | H228: 0.0025 | I228: 4000 | J228: 4400 | K228: 1 | L228: 400 | M228: 0 | N228: 0 | O228: 0 | P228: 0 | Q228: 0 | R228: 4000 | S228: 4210.5263 | T228: 0.05 | U228: 400 | V228: DTC
A229: 45975 | B229: 4211 | C229: 4000 | D229: 1 | E229: 1 | F229: 0.05 | G229: 400 | H229: 0.0025 | I229: 4000 | J229: 4400 | K229: 1 | L229: 400 | M229: 0 | N229: 0 | O229: 0 | P229: 0 | Q229: 0 | R229: 4000 | S229: 4210.5263 | T229: 0.05 | U229: 400 | V229: DTC
A230: 45976 | B230: 4211 | C230: 4000 | D230: 1 | E230: 1 | F230: 0.05 | G230: 400 | H230: 0.0025 | I230: 4000 | J230: 4400 | K230: 1 | L230: 400 | M230: 0 | N230: 0 | O230: 0 | P230: 0 | Q230: 0 | R230: 4000 | S230: 4210.5263 | T230: 0.05 | U230: 400 | V230: DTC
A231: 45977 | B231: 0 | C231: 0 | D231: 0 | E231: 0 | F231: 0 | G231: 400 | H231: 0 | I231: 0 | J231: 0 | K231: 0 | L231: 400 | M231: 0 | N231: 0 | O231: 0 | P231: 0 | Q231: 0 | R231: 0 | S231: 0 | T231: 0 | U231: 400 | V231: DTC
A232: 45978 | B232: 4211 | C232: 4000 | D232: 1 | E232: 1 | F232: 0.05 | G232: 400 | H232: 0.0025 | I232: 4000 | J232: 4400 | K232: 1 | L232: 400 | M232: 0 | N232: 0 | O232: 0 | P232: 0 | Q232: 0 | R232: 4000 | S232: 4210.5263 | T232: 0.05 | U232: 400 | V232: DTC
A233: 45979 | B233: 4211 | C233: 4000 | D233: 1 | E233: 1 | F233: 0.05 | G233: 400 | H233: 0.0025 | I233: 4000 | J233: 4400 | K233: 1 | L233: 400 | M233: 0 | N233: 0 | O233: 0 | P233: 0 | Q233: 0 | R233: 4000 | S233: 4210.5263 | T233: 0.05 | U233: 400 | V233: DTC
A234: 45980 | B234: 0 | C234: 0 | D234: 0 | E234: 0 | F234: 0 | G234: 400 | H234: 0 | I234: 0 | J234: 0 | K234: 0 | L234: 400 | M234: 0 | N234: 0 | O234: 0 | P234: 0 | Q234: 0 | R234: 0 | S234: 0 | T234: 0 | U234: 400 | V234: DTC
A235: 45981 | B235: 4211 | C235: 4000 | D235: 1 | E235: 1 | F235: 0.05 | G235: 400 | H235: 0.0025 | I235: 4000 | J235: 4400 | K235: 1 | L235: 400 | M235: 0 | N235: 0 | O235: 0 | P235: 0 | Q235: 0 | R235: 4000 | S235: 4210.5263 | T235: 0.05 | U235: 400 | V235: DTC
A236: 45982 | B236: 4211 | C236: 4000 | D236: 1 | E236: 1 | F236: 0.05 | G236: 400 | H236: 0.0025 | I236: 4000 | J236: 4400 | K236: 1 | L236: 400 | M236: 0 | N236: 0 | O236: 0 | P236: 0 | Q236: 0 | R236: 4000 | S236: 4210.5263 | T236: 0.05 | U236: 400 | V236: DTC
A237: 45983 | B237: 0 | C237: 0 | D237: 0 | E237: 0 | F237: 0 | G237: 400 | H237: 0 | I237: 0 | J237: 0 | K237: 0 | L237: 400 | M237: 0 | N237: 0 | O237: 0 | P237: 0 | Q237: 0 | R237: 0 | S237: 0 | T237: 0 | U237: 400 | V237: DTC
A238: 45984 | B238: 4211 | C238: 4000 | D238: 1 | E238: 1 | F238: 0.05 | G238: 400 | H238: 0.0025 | I238: 4000 | J238: 4400 | K238: 1 | L238: 400 | M238: 0 | N238: 0 | O238: 0 | P238: 0 | Q238: 0 | R238: 4000 | S238: 4210.5263 | T238: 0.05 | U238: 400 | V238: DTC
A239: 45985 | B239: 4211 | C239: 4000 | D239: 1 | E239: 1 | F239: 0.05 | G239: 400 | H239: 0.0025 | I239: 4000 | J239: 4400 | K239: 1 | L239: 400 | M239: 0 | N239: 0 | O239: 0 | P239: 0 | Q239: 0 | R239: 4000 | S239: 4210.5263 | T239: 0.05 | U239: 400 | V239: DTC
... A276: 46022 | B276: 0 | C276: 0 | D276: 0 | E276: 0 | F276: 0 | G276: 400 | H276: 0 | I276: 0 | J276: 0 | K276: 0 | L276: 400 | M276: 0 | N276: 0 | O276: 0 | P276: 0 | Q276: 0 | R276: 0 | S276: 0 | T276: 0 | U276: 400 | V276: DTC
A277: 44652 | B277: 20000 | C277: 12000 | D277: 3 | E277: 5 | F277: 0.4 | G277: 8000 | H277: 0.0005 | I277: 4000 | J277: 5000 | K277: 4 | L277: 5000 | M277: 3894 | V277: PFS
A278: 44653 | B278: 22000 | C278: 13200 | D278: 3 | E278: 6 | F278: 0.4 | G278: 8000 | H278: 0.00055 | I278: 4000 | J278: 5000 | K278: 4 | L278: 5000 | M278: 3894 | V278: PFS
A279: 44654 | B279: 22000 | C279: 13200 | D279: 3 | E279: 6 | F279: 0.4 | G279: 8000 | H279: 0.00055 | I279: 4000 | J279: 5000 | K279: 4 | L279: 5000 | M279: 3894 | V279: PFS
A280: 44655 | B280: 20000 | C280: 12000 | D280: 3 | E280: 5 | F280: 0.4 | G280: 8000 | H280: 0.0005 | I280: 4000 | J280: 5000 | K280: 4 | L280: 5000 | M280: 3894 | V280: PFS
A281: 44656 | B281: 20000 | C281: 12000 | D281: 3 | E281: 5 | F281: 0.4 | G281: 8000 | H281: 0.0005 | I281: 4000 | J281: 5000 | K281: 4 | L281: 5000 | M281: 3894 | V281: PFS
A282: 44657 | B282: 20000 | C282: 12000 | D282: 3 | E282: 5 | F282: 0.4 | G282: 8000 | H282: 0.0005 | I282: 4000 | J282: 5000 | K282: 4 | L282: 5000 | M282: 3894 | V282: PFS
A283: 44658 | B283: 20000 | C283: 12000 | D283: 3 | E283: 5 | F283: 0.4 | G283: 8000 | H283: 0.0005 | I283: 4000 | J283: 5000 | K283: 4 | L283: 5000 | M283: 3894 | V283: PFS
A284: 44659 | B284: 20000 | C284: 12000 | D284: 3 | E284: 5 | F284: 0.4 | G284: 8000 | H284: 0.0005 | I284: 4000 | J284: 5000 | K284: 4 | L284: 5000 | M284: 3894 | V284: PFS
A285: 44660 | B285: 22000 | C285: 13200 | D285: 3 | E285: 6 | F285: 0.4 | G285: 8000 | H285: 0.00055 | I285: 4000 | J285: 5000 | K285: 4 | L285: 5000 | M285: 3894 | V285: PFS
A286: 44661 | B286: 22000 | C286: 13200 | D286: 3 | E286: 6 | F286: 0.4 | G286: 8000 | H286: 0.00055 | I286: 4000 | J286: 5000 | K286: 4 | L286: 5000 | M286: 3894 | V286: PFS
A287: 44662 | B287: 20000 | C287: 12000 | D287: 3 | E287: 5 | F287: 0.4 | G287: 8000 | H287: 0.0005 | I287: 4000 | J287: 5000 | K287: 4 | L287: 5000 | M287: 3894 | V287: PFS
A288: 44663 | B288: 20000 | C288: 12000 | D288: 3 | E288: 5 | F288: 0.4 | G288: 8000 | H288: 0.0005 | I288: 4000 | J288: 5000 | K288: 4 | L288: 5000 | M288: 3894 | V288: PFS
...

Sheet Campaign
D1: 税率 | E1: 1.13
D2: 汇率 | E2: 7.7897
D3: YTD NETSALES | E3: 16359478 | F3: LY YTD NETSALES | G3: 17265765 | J3: 25.10.10-25.11.14 vs 24.10.12-24.11.11 | R3: 25.12.05-25.12.14 vs 24.12.05-24.12.14 | W3: 5.15-5.20 | AB3: 25.7.29-25.8.29 vs 24.7.10-24.8.10 | AJ3: 1.2-2.4 vs 24.1.15-24.2.17
D4: KPI | E4: COMPAIGN | W4: BRANDING
E5: 618 | J5: D11 | R5: D12 | W5: 520 | AB5: CVD | AJ5: CNY
E6: Actual | F6: Actual Excl. Tax | G6: LY Actual | H6: LY Actual Excl. Tax | I6: YOY | J6: Actual | K6: Actual Excl. Tax | L6: LY Actual | M6: LY Actual Excl. Tax | N6: YOY | O6: Target | P6: Target Excl. Tax | Q6: ACH | R6: Actual | S6: Actual Excl. Tax | T6: LY Actual | U6: LY Actual Excl. Tax | V6: YOY | W6: Actual | X6: Actual Excl. Tax | Y6: LY Actual | Z6: LY Actual Excl. Tax | AA6: YOY | AB6: Actual | AC6: Actual Excl. Tax | AD6: LY Actual | AE6: LY Actual Excl. Tax | AF6: YOY | AG6: HEYBOX | AH6: LY | AI6: YOY | AJ6: Actual | AK6: Actual Excl. Tax | AL6: LY Actual | AM6: LY Actual Excl. Tax | AN6: YOY
D7: GMV | E7: 11325324 | F7: =E7/$E$1 -> 10022411 | G7: 10119976 | H7: =G7/$E$1 -> 8955731 | I7: =E7/G7-1 -> 0.11910582 | J7: 12523240 | K7: =J7/$E$1 -> 11082513 | L7: 24599284 | M7: =L7/$E$1 -> 21769278 | N7: =J7/L7-1 -> -0.49091041 | O7: 19600076 | P7: =O7/$E$1 -> 17345200 | Q7: =J7/O7 -> 0.63893831 | R7: 3578274 | S7: =R7/$E$1 -> 3166614.2 | T7: 3487451.5 | U7: =T7/$E$1 -> 3086240.3 | V7: =R7/T7-1 -> 0.026042656 | W7: 777106.5 | X7: =W7/$E$1 -> 687704.87 | Y7: 400829 | Z7: =Y7/$E$1 -> 354715.93 | AA7: =W7/Y7-1 -> 0.93874819 | AB7: 1972931 | AC7: =AB7/$E$1 -> 1745956.6 | AD7: 1189925 | AE7: =AD7/$E$1 -> 1053031 | AF7: =AB7/AD7-1 -> 0.65802971 | AG7: 1264099 | AH7: 836139 | AI7: =AG7/AH7-1 -> 0.51182877 | AJ7: 3496040 | AK7: =AJ7/$E$1 -> 3093840.7 | AL7: 2728422 | AM7: =AL7/$E$1 -> 2414532.7 | AN7: =AJ7/AL7-1 -> 0.28134138
D8: GMV excl.cancel | J8: 10135164 | K8: =J8/$E$1 -> 8969172.1 | L8: 12952860 | M8: =L8/$E$1 -> 11462708 | N8: =J8/L8-1 -> -0.21753464 | O8: 13201601 | P8: =O8/$E$1 -> 11682833 | Q8: =J8/O8 -> 0.76772237 | R8: 2852723.4 | S8: =R8/$E$1 -> 2524533.9 | T8: 2826656.3 | U8: =T8/$E$1 -> 2501465.8 | V8: =R8/T8-1 -> 0.009221864
D9: NET | E9: 4589188 | F9: =E9/$E$1 -> 4061228.3 | G9: 4026797 | H9: =G9/$E$1 -> 3563537.2 | I9: =E9/G9-1 -> 0.13966212 | J9: 5396622 | K9: =J9/$E$1 -> 4775771.7 | L9: 6697736.8 | M9: =L9/$E$1 -> 5927200.7 | N9: =J9/L9-1 -> -0.19426186 | O9: 7851332.9 | P9: =O9/$E$1 -> 6948082.2 | Q9: =J9/O9 -> 0.68735106 | R9: 1412423.7 | S9: =R9/$E$1 -> 1249932.5 | T9: 1507445.8 | U9: =T9/$E$1 -> 1334022.8 | V9: =R9/T9-1 -> -0.063035136 | W9: =W7-W19 -> 406459 | X9: =W9/$E$1 -> 359698.23 | Y9: =Y7-Y19 -> 197392 | Z9: =Y9/$E$1 -> 174683.19 | AA9: =W9/Y9-1 -> 1.0591463 | AB9: 940871 | AC9: =AB9/$E$1 -> 832629.2 | AD9: 635874.04 | AE9: =AD9/$E$1 -> 562720.39 | AF9: =AB9/AD9-1 -> 0.47964996 | AG9: 616151 | AH9: 356135 | AI9: =AG9/AH9-1 -> 0.73010516 | AJ9: 1709126 | AK9: =AJ9/$E$1 -> 1512500.9 | AL9: 1513346 | AM9: =AL9/$E$1 -> 1339244.2 | AN9: =AJ9/AL9-1 -> 0.12936896
D10: UV | E10: 1084849 | F10: =E10 -> 1084849 | G10: 1352483 | H10: =G10 -> 1352483 | I10: =E10/G10-1 -> -0.19788345 | J10: =1749310-51481 -> 1697829 | K10: =J10 -> 1697829 | L10: 799113 | M10: =L10 -> 799113 | N10: =J10/L10-1 -> 1.1246419 | O10: 1228657 | P10: =O10 -> 1228657 | Q10: =J10/O10 -> 1.3818576 | R10: 421317 | S10: =R10 -> 421317 | T10: 189099 | U10: =T10 -> 189099 | V10: =R10/T10-1 -> 1.2280234 | W10: 220633 | X10: =W10 -> 220633 | Y10: 82077 | Z10: =Y10 -> 82077 | AA10: =W10/Y10-1 -> 1.6881221 | AB10: 405491 | AC10: =AB10 -> 405491 | AD10: 457837 | AE10: =AD10 -> 457837 | AF10: =AB10/AD10-1 -> -0.11433327 | AG10: 485354 | AH10: 727771 | AI10: =AG10/AH10-1 -> -0.33309516 | AJ10: 467429 | AK10: =AJ10 -> 467429 | AL10: 377818 | AM10: =AL10 -> 377818 | AN10: =AJ10/AL10-1 -> 0.23718034
D11: Buyers | E11: 3262 | F11: =E11 -> 3262 | G11: 3232 | H11: =G11 -> 3232 | I11: =E11/G11-1 -> 0.0092821782 | J11: 2494 | K11: =J11 -> 2494 | L11: 5201 | M11: =L11 -> 5201 | N11: =J11/L11-1 -> -0.52047683 | O11: 4597 | P11: =O11 -> 4597 | Q11: =J11/O11 -> 0.54252774 | R11: 618 | S11: =R11 -> 618 | T11: 651 | U11: =T11 -> 651 | V11: =R11/T11-1 -> -0.050691244 | W11: 228 | X11: =W11 -> 228 | Y11: 91 | Z11: =Y11 -> 91 | AA11: =W11/Y11-1 -> 1.5054945 | AB11: 397 | AC11: =AB11 -> 397 | AD11: 262 | AE11: =AD11 -> 262 | AF11: =AB11/AD11-1 -> 0.51526718 | AG11: 197 | AH11: 142 | AI11: =AG11/AH11-1 -> 0.38732394 | AJ11: 501 | AK11: =AJ11 -> 501 | AL11: 411 | AM11: =AL11 -> 411 | AN11: =AJ11/AL11-1 -> 0.2189781
D12: Units | E12: 4089 | F12: =E12 -> 4089 | G12: 4171 | H12: =G12 -> 4171 | I12: =E12/G12-1 -> -0.019659554 | J12: 3149 | K12: =J12 -> 3149 | L12: 6619 | M12: =L12 -> 6619 | N12: =J12/L12-1 -> -0.52424838 | O12: 5976.1 | P12: =O12 -> 5976.1 | Q12: =J12/O12 -> 0.52693228 | R12: 768 | S12: =R12 -> 768 | T12: 839 | U12: =T12 -> 839 | V12: =R12/T12-1 -> -0.084624553 | W12: 274 | X12: =W12 -> 274 | Y12: 105 | Z12: =Y12 -> 105 | AA12: =W12/Y12-1 -> 1.6095238 | AB12: 515 | AC12: =AB12 -> 515 | AD12: 325 | AE12: =AD12 -> 325 | AF12: =AB12/AD12-1 -> 0.58461538 | AG12: 230 | AH12: 146 | AI12: =AG12/AH12-1 -> 0.57534247 | AJ12: 631 | AK12: =AJ12 -> 631 | AL12: 492 | AM12: =AL12 -> 492 | AN12: =AJ12/AL12-1 -> 0.28252033
D13: CR | E13: =E11/E10 -> 0.0030068701 | F13: =F11/F10 -> 0.0030068701 | G13: =G11/G10 -> 0.0023896788 | H13: =H11/H10 -> 0.0023896788 | I13: =E13/G13-1 -> 0.25827372 | J13: =J11/J10 -> 0.0014689347 | K13: =K11/K10 -> 0.0014689347 | L13: =L11/L10 -> 0.0065084663 | M13: =M11/M10 -> 0.0065084663 | N13: =J13/L13-1 -> -0.77430401 | O13: =O11/O10 -> 0.0037414836 | P13: =P11/P10 -> 0.0037414836 | Q13: =J13/O13 -> 0.39260756 | R13: =R11/R10 -> 0.001466829 | S13: =S11/S10 -> 0.001466829 | T13: =T11/T10 -> 0.0034426412 | U13: =U11/U10 -> 0.0034426412 | V13: =R13/T13-1 -> -0.57392335 | W13: =W11/W10 -> 0.0010333903 | X13: =X11/X10 -> 0.0010333903 | Y13: =Y11/Y10 -> 0.001108715 | Z13: =Z11/Z10 -> 0.001108715 | AA13: =W13/Y13-1 -> -0.067938738 | AB13: =AB11/AB10 -> 0.00097905995 | AC13: =AC11/AC10 -> 0.00097905995 | AD13: =AD11/AD10 -> 0.00057225606 | AE13: =AE11/AE10 -> 0.00057225606 | AF13: =AB13/AD13-1 -> 0.71087738 | AG13: =AG11/AG10 -> 0.00040588931 | AH13: =AH11/AH10 -> 0.00019511632 | AI13: =AG13/AH13-1 -> 1.0802427 | AJ13: =AJ11/AJ10 -> 0.0010718205 | AK13: =AK11/AK10 -> 0.0010718205 | AL13: =AL11/AL10 -> 0.0010878254 | AM13: =AM11/AM10 -> 0.0010878254 | AN13: =AJ13/AL13-1 -> -0.014712676
D14: ATV | E14: =E7/E11 -> 3471.8958 | F14: =F7/F11 -> 3072.4741 | G14: =G7/G11 -> 3131.1807 | H14: =H7/H11 -> 2770.9564 | I14: =E14/G14-1 -> 0.10881361 | J14: =J7/J11 -> 5021.3471 | K14: =K7/K11 -> 4443.67 | L14: =L7/L11 -> 4729.7221 | M14: =M7/M11 -> 4185.5948 | N14: =J14/L14-1 -> 0.061657966 | O14: =O7/O11 -> 4263.6668 | P14: =P7/P11 -> 3773.1565 | Q14: =J14/O14 -> 1.1777063 | R14: =R7/R11 -> 5790.0874 | S14: =S7/S11 -> 5123.9711 | T14: =T7/T11 -> 5357.0684 | U14: =U7/U11 -> 4740.7685 | V14: =R14/T14-1 -> 0.080831342 | W14: =W7/W11 -> 3408.3618 | X14: =X7/X11 -> 3016.2494 | Y14: =Y7/Y11 -> 4404.7143 | Z14: =Z7/Z11 -> 3897.9772 | AA14: =W14/Y14-1 -> -0.22620138 | AB14: =AB7/AB11 -> 4969.5995 | AC14: =AC7/AC11 -> 4397.8757 | AD14: =AD7/AD11 -> 4541.6985 | AE14: =AE7/AE11 -> 4019.2022 | AF14: =AB14/AD14-1 -> 0.094216079 | AG14: =AG7/AG11 -> 6416.7462 | AH14: =AH7/AH11 -> 5888.3028 | AI14: =AG14/AH14-1 -> 0.089744599 | AJ14: =AJ7/AJ11 -> 6978.1238 | AK14: =AK7/AK11 -> 6175.3308 | AL14: =AL7/AL11 -> 6638.4964 | AM14: =AM7/AM11 -> 5874.7755 | AN14: =AJ14/AL14-1 -> 0.051160291
D15: AUR | E15: =E7/E12 -> 2769.7051 | F15: =F7/F12 -> 2451.0664 | G15: =G7/G12 -> 2426.2709 | H15: =H7/H12 -> 2147.1424 | I15: =E15/G15-1 -> 0.14154814 | J15: =J7/J12 -> 3976.8942 | K15: =K7/K12 -> 3519.3754 | L15: =L7/L12 -> 3716.4654 | M15: =M7/M12 -> 3288.9074 | N15: =J15/L15-1 -> 0.070074311 | O15: =O7/O12 -> 3279.7437 | P15: =P7/P12 -> 2902.4281 | Q15: =J15/O15 -> 1.2125625 | R15: =R7/R12 -> 4659.2109 | S15: =S7/S12 -> 4123.1955 | T15: =T7/T12 -> 4156.6764 | U15: =U7/U12 -> 3678.4747 | V15: =R15/T15-1 -> 0.12089816 | W15: =W7/W12 -> 2836.1551 | X15: =X7/X12 -> 2509.8718 | Y15: =Y7/Y12 -> 3817.419 | Z15: =Z7/Z12 -> 3378.2469 | AA15: =W15/Y15-1 -> -0.25704905 | AB15: =AB7/AB12 -> 3830.934 | AC15: =AC7/AC12 -> 3390.2071 | AD15: =AD7/AD12 -> 3661.3077 | AE15: =AE7/AE12 -> 3240.0953 | AF15: =AB15/AD15-1 -> 0.046329427 | AG15: =AG7/AG12 -> 5496.0826 | AH15: =AH7/AH12 -> 5726.9795 | AI15: =AG15/AH15-1 -> -0.040317386 | AJ15: =AJ7/AJ12 -> 5540.4754 | AK15: =AK7/AK12 -> 4903.0756 | AL15: =AL7/AL12 -> 5545.5732 | AM15: =AM7/AM12 -> 4907.5869 | AN15: =AJ15/AL15-1 -> -0.00091924401
D16: UPT | E16: =ROUND(E12/E11,2) -> 1.25 | F16: =ROUND(F12/F11,2) -> 1.25 | G16: =ROUND(G12/G11,2) -> 1.29 | H16: =ROUND(H12/H11,2) -> 1.29 | I16: =E16/G16-1 -> -0.031007752 | J16: =ROUND(J12/J11,2) -> 1.26 | K16: =ROUND(K12/K11,2) -> 1.26 | L16: =ROUND(L12/L11,2) -> 1.27 | M16: =ROUND(M12/M11,2) -> 1.27 | N16: =J16/L16-1 -> -0.0078740157 | O16: =ROUND(O12/O11,2) -> 1.3 | P16: =ROUND(P12/P11,2) -> 1.3 | Q16: =J16/O16 -> 0.96923077 | R16: =ROUND(R12/R11,2) -> 1.24 | S16: =ROUND(S12/S11,2) -> 1.24 | T16: =ROUND(T12/T11,2) -> 1.29 | U16: =ROUND(U12/U11,2) -> 1.29 | V16: =R16/T16-1 -> -0.03875969 | W16: =ROUND(W12/W11,2) -> 1.2 | X16: =ROUND(X12/X11,2) -> 1.2 | Y16: =ROUND(Y12/Y11,2) -> 1.15 | Z16: =ROUND(Z12/Z11,2) -> 1.15 | AA16: =W16/Y16-1 -> 0.043478261 | AB16: =ROUND(AB12/AB11,2) -> 1.3 | AC16: =ROUND(AC12/AC11,2) -> 1.3 | AD16: =ROUND(AD12/AD11,2) -> 1.24 | AE16: =ROUND(AE12/AE11,2) -> 1.24 | AF16: =AB16/AD16-1 -> 0.048387097 | AG16: =ROUND(AG12/AG11,2) -> 1.17 | AH16: =ROUND(AH12/AH11,2) -> 1.03 | AI16: =AG16/AH16-1 -> 0.13592233 | AJ16: =ROUND(AJ12/AJ11,2) -> 1.26 | AK16: =ROUND(AK12/AK11,2) -> 1.26 | AL16: =ROUND(AL12/AL11,2) -> 1.2 | AM16: =ROUND(AM12/AM11,2) -> 1.2 | AN16: =AJ16/AL16-1 -> 0.05
D17: RRC | E17: =1-E9/E7 -> 0.59478528 | F17: =1-F9/F7 -> 0.59478528 | G17: =1-G9/G7 -> 0.60209421 | H17: =1-H9/H7 -> 0.60209421 | I17: =(E17-G17)*100 -> -0.7308935 | J17: =1-J9/J7 -> 0.56907141 | K17: =1-K9/K7 -> 0.56907141 | L17: =1-L9/L7 -> 0.72772636 | M17: =1-M9/M7 -> 0.72772636 | N17: =(J17-L17)*100 -> -15.865495 | O17: =1-O9/O7 -> 0.59942335 | P17: =1-P9/P7 -> 0.59942335 | Q17: =J17/O17 -> 0.94936476 | R17: =1-R9/R7 -> 0.60527793 | S17: =1-S9/S7 -> 0.60527793 | T17: =1-T9/T7 -> 0.56775147 | U17: =1-U9/U7 -> 0.56775147 | V17: =(R17-T17)*100 -> 3.7526456 | W17: =1-W9/W7 -> 0.47695843 | X17: =1-X9/X7 -> 0.47695843 | Y17: =1-Y9/Y7 -> 0.50754062 | Z17: =1-Z9/Z7 -> 0.50754062 | AA17: =(W17-Y17)*100 -> -3.0582187 | AB17: =1-AB9/AB7 -> 0.52311003 | AC17: =1-AC9/AC7 -> 0.52311003 | AD17: =1-AD9/AD7 -> 0.46561839 | AE17: =1-AE9/AE7 -> 0.46561839 | AF17: =(AB17-AD17)*100 -> 5.7491645 | AG17: =1-AG9/AG7 -> 0.51257694 | AH17: =1-AH9/AH7 -> 0.57407201 | AI17: =AG17-AH17 -> -0.061495072 | AJ17: =1-AJ9/AJ7 -> 0.51112516 | AK17: =1-AK9/AK7 -> 0.51112516 | AL17: =1-AL9/AL7 -> 0.4453402 | AM17: =1-AM9/AM7 -> 0.4453402 | AN17: =(AJ17-AL17)*100 -> 6.5784958
D18: RRC after shift | J18: =(J19-(J7-J8))/J8 -> 0.46753484 | K18: =(K19-(K7-K8))/K8 -> 0.46753484 | L18: =(L19-(L7-L8))/L8 -> 0.48291446 | M18: =(M19-(M7-M8))/M8 -> 0.48291446 | N18: =(J18-L18)*100 -> -1.5379623 | O18: =(O19-(O7-O8))/O8 -> 0.40527419 | P18: =(P19-(P7-P8))/P8 -> 0.40527419 | Q18: =J18/O18 -> 1.153626 | R18: =(R19-(R7-R8))/R8 -> 0.50488584 | S18: =(S19-(S7-S8))/S8 -> 0.50488584 | T18: =(T19-(T7-T8))/T8 -> 0.46670355 | U18: =(U19-(U7-U8))/U8 -> 0.46670355 | V18: =(R18-T18)*100 -> 3.818229
D19: RR | E19: 5384247.9 | F19: =E19/$E$1 -> 4764821.2 | G19: 2919351.2 | H19: =G19/$E$1 -> 2583496.6 | I19: =E19/G19-1 -> 0.84433032 | J19: =J7-J9 -> 7126617.7 | K19: =J19/$E$1 -> 6306741.3 | L19: =L7-L9 -> 17901548 | M19: =L19/$E$1 -> 15842078 | N19: =J19/L19-1 -> -0.60189935 | O19: =O7-O9 -> 11748744 | P19: =O19/$E$1 -> 10397118 | Q19: =J19/O19 -> 0.60658552 | R19: =R7-R9 -> 2165850.3 | S19: =R19/$E$1 -> 1916681.7 | T19: =T7-T9 -> 1980005.7 | U19: =T19/$E$1 -> 1752217.5 | V19: =R19/T19-1 -> 0.093860613 | W19: 370647.5 | X19: =W19/$E$1 -> 328006.64 | Y19: 203437 | Z19: =Y19/$E$1 -> 180032.74 | AA19: =W19/Y19-1 -> 0.82192767 | AB19: =AB7-AB9 -> 1032060 | AC19: =AB19/$E$1 -> 913327.43 | AD19: =AD7-AD9 -> 554050.96 | AE19: =AD19/$E$1 -> 490310.58 | AF19: =AB19/AD19-1 -> 0.86275284 | AG19: =AG7-AG9 -> 647948 | AH19: =AH7-AH9 -> 480004 | AI19: =AG19/AH19-1 -> 0.34988042 | AJ19: =AJ7-AJ9 -> 1786914 | AK19: =AJ19/$E$1 -> 1581339.8 | AL19: =AL7-AL9 -> 1215076 | AM19: =AL19/$E$1 -> 1075288.5 | AN19: =AJ19/AL19-1 -> 0.47061912
D20: Pre-Sales | E20: 0 | F20: =E20/$E$1 -> 0 | G20: 691643 | H20: =G20/$E$1 -> 612073.45 | I20: =E20/G20-1 -> -1 | J20: 61702.1 | K20: =J20/$E$1 -> 54603.628 | L20: 2424202.1 | M20: =L20/$E$1 -> 2145311.6 | N20: =J20/L20-1 -> -0.97454746 | O20: =N20/$E$1 -> -0.86243138 | P20: =O20/$E$1 -> -0.76321361 | Q20: =J20/O20 -> -71544.359 | R20: 0 | S20: =R20/$E$1 -> 0 | T20: 0 | U20: =T20/$E$1 -> 0 | V20: =R20/T20-1 -> #DIV/0! | W20: 0 | Y20: 0 | AA20: =W20/Y20-1 -> #DIV/0! | AB20: 0 | AC20: 0 | AD20: 0 | AE20: 0 | AF20: =AB20/AD20-1 -> #DIV/0! | AJ20: 0 | AK20: =AJ20/$E$1 -> 0 | AL20: 0 | AM20: =AL20/$E$1 -> 0 | AN20: =AJ20/AL20-1 -> #DIV/0!
D21: Pre-Sales% | E21: =E20/E7 -> 0 | F21: =F20/F7 -> 0 | G21: =G20/G7 -> 0.068344332 | H21: =H20/H7 -> 0.068344332 | I21: =(E21-G21)*100 -> -6.8344332 | J21: =J20/J7 -> 0.0049270078 | K21: =K20/K7 -> 0.0049270078 | L21: =L20/L7 -> 0.098547667 | M21: =M20/M7 -> 0.098547667 | N21: =(J21-L21)*100 -> -9.3620659 | O21: =O20/O7 -> -4.4001429e-08 | P21: =P20/P7 -> -4.4001429e-08 | Q21: =J21/O21 -> -111973.81 | R21: =R20/R7 -> 0 | S21: =S20/S7 -> 0 | T21: =T20/T7 -> 0 | U21: =U20/U7 -> 0 | V21: =(R21-T21)*100 -> 0 | W21: =W20/W7 -> 0 | X21: =X20/X7 -> 0 | Y21: =Y20/Y7 -> 0 | Z21: =Z20/Z7 -> 0 | AA21: =(W21-Y21)*100 -> 0 | AB21: =AB20/AB7 -> 0 | AC21: =AC20/AC7 -> 0 | AD21: =AD20/AD7 -> 0 | AE21: =AE20/AE7 -> 0 | AF21: =(AB21-AD21)*100 -> 0 | AJ21: =AJ20/AJ7 -> 0 | AK21: =AK20/AK7 -> 0 | AL21: =AL20/AL7 -> 0 | AM21: =AM20/AM7 -> 0 | AN21: =(AJ21-AL21)*100 -> 0
D22: MD GMV | E22: 7085063 | F22: =E22/$E$1 -> 6269967.3 | G22: 6690988 | H22: =G22/$E$1 -> 5921228.3 | I22: =E22/G22-1 -> 0.058896384 | K22: =J22/$E$1 -> 0 | M22: =L22/$E$1 -> 0 | N22: =J22/L22-1 -> #DIV/0! | O22: =N22/$E$1 -> #DIV/0! | P22: =O22/$E$1 -> #DIV/0! | Q22: =J22/O22 -> #DIV/0! | R22: 2387703 | S22: =R22/$E$1 -> 2113011.5 | T22: 1432008 | U22: =T22/$E$1 -> 1267263.7 | V22: =R22/T22-1 -> 0.66738105 | W22: 403529.48 | X22: =W22/$E$1 -> 357105.73 | Y22: 20825 | Z22: =Y22/$E$1 -> 18429.204 | AA22: =W22/Y22-1 -> 18.377166 | AB22: 543440 | AC22: =AB22/$E$1 -> 480920.35 | AD22: 148965 | AE22: =AD22/$E$1 -> 131827.43 | AF22: =AB22/AD22-1 -> 2.6481053 | AG22: 606933 | AH22: 278239 | AI22: =AG22/AH22-1 -> 1.1813369 | AJ22: 1822588 | AK22: =AJ22/$E$1 -> 1612909.7 | AL22: 701092 | AM22: =AL22/$E$1 -> 620435.4 | AN22: =AJ22/AL22-1 -> 1.5996417
D23: GMV MD% | E23: =E22/E7 -> 0.62559473 | F23: =F22/F7 -> 0.62559473 | G23: =G22/G7 -> 0.66116639 | H23: =H22/H7 -> 0.66116639 | I23: =(E23-G23)*100 -> -3.5571661 | J23: =J22/J7 -> 0 | K23: =K22/K7 -> 0 | L23: =L22/L7 -> 0 | M23: =M22/M7 -> 0 | N23: =(J23-L23)*100 -> 0 | O23: =O22/O7 -> #DIV/0! | P23: =P22/P7 -> #DIV/0! | Q23: =J23/O23 -> #DIV/0! | R23: =R22/R7 -> 0.66727786 | S23: =S22/S7 -> 0.66727786 | T23: =T22/T7 -> 0.41061732 | U23: =U22/U7 -> 0.41061732 | V23: =(R23-T23)*100 -> 25.666053 | W23: =W22/W7 -> 0.51927179 | X23: =X22/X7 -> 0.51927179 | Y23: =Y22/Y7 -> 0.051954824 | Z23: =Z22/Z7 -> 0.051954824 | AA23: =(W23-Y23)*100 -> 46.731696 | AB23: =AB22/AB7 -> 0.27544805 | AC23: =AC22/AC7 -> 0.27544805 | AD23: =AD22/AD7 -> 0.12518856 | AE23: =AE22/AE7 -> 0.12518856 | AF23: =(AB23-AD23)*100 -> 15.025949 | AG23: =AG22/AG7 -> 0.48013091 | AH23: =AH22/AH7 -> 0.33276644 | AI23: =AG23-AH23 -> 0.14736447 | AJ23: =AJ22/AJ7 -> 0.52132928 | AK23: =AK22/AK7 -> 0.52132928 | AL23: =AL22/AL7 -> 0.25695878 | AM23: =AM22/AM7 -> 0.25695878 | AN23: =(AJ23-AL23)*100 -> 26.437049
D24: MD NET | E24: 3136625 | F24: =E24/$E$1 -> 2775774.3 | G24: 2955211 | H24: =G24/$E$1 -> 2615231 | I24: =E24/G24-1 -> 0.061387833 | J24: 4309259 | K24: =J24/$E$1 -> 3813503.5 | L24: 5705730 | M24: =L24/$E$1 -> 5049318.6 | N24: =J24/L24-1 -> -0.24474887 | O24: =N24/$E$1 -> -0.21659192 | P24: =O24/$E$1 -> -0.19167427 | R24: 964769 | S24: =R24/$E$1 -> 853777.88 | T24: 1226011 | U24: =T24/$E$1 -> 1084965.5 | V24: =R24/T24-1 -> -0.21308292 | AA24: =W24/Y24-1 -> #DIV/0! | AB24: 200688 | AC24: =AB24/$E$1 -> 177600 | AD24: 74290 | AE24: =AD24/$E$1 -> 65743.363 | AF24: =AB24/AD24-1 -> 1.7014134 | AJ24: 793568 | AK24: =AJ24/$E$1 -> 702272.57 | AL24: 333169 | AM24: =AL24/$E$1 -> 294839.82 | AN24: =AJ24/AL24-1 -> 1.3818783
D25: NET MD% | E25: =E24/E9 -> 0.68348148 | F25: =F24/F9 -> 0.68348148 | G25: =G24/G9 -> 0.73388626 | H25: =H24/H9 -> 0.73388626 | I25: =(E25-G25)*100 -> -5.0404784 | J25: =J24/J9 -> 0.79851044 | K25: =K24/K9 -> 0.79851044 | L25: =L24/L9 -> 0.85188925 | M25: =M24/M9 -> 0.85188925 | N25: =(J25-L25)*100 -> -5.3378814 | O25: 0.75 | P25: =O25 -> 0.75 | R25: =R24/R9 -> 0.68305918 | S25: =S24/S9 -> 0.68305918 | T25: =T24/T9 -> 0.81330355 | U25: =U24/U9 -> 0.81330355 | V25: =(R25-T25)*100 -> -13.024436 | AA25: =(W25-Y25)*100 -> 0 | AB25: =AB24/AB9 -> 0.21330023 | AC25: =AC24/AC9 -> 0.21330023 | AD25: =AD24/AD9 -> 0.11683131 | AE25: =AE24/AE9 -> 0.11683131 | AF25: =(AB25-AD25)*100 -> 9.6468915 | AJ25: =AJ24/AJ9 -> 0.46431217 | AK25: =AK24/AK9 -> 0.46431217 | AL25: =AL24/AL9 -> 0.22015388 | AM25: =AM24/AM9 -> 0.22015388 | AN25: =(AJ25-AL25)*100 -> 24.415828
D26: NET SHARE% | E26: =E9/$E$3 -> 0.28052166 | F26: =E26 -> 0.28052166 | G26: =G9/$G$3 -> 0.23322436 | H26: =G26 -> 0.23322436 | I26: =(E26-G26)*100 -> 4.7297304 | J26: =J9/$E$3 -> 0.3298774 | K26: =J26 -> 0.3298774 | L26: =L9/$G$3 -> 0.38792007 | M26: =L26 -> 0.38792007 | N26: =(J26-L26)*100 -> -5.8042674 | R26: =R9/$E$3 -> 0.086336724 | S26: =R26 -> 0.086336724 | T26: =T9/$G$3 -> 0.087308369 | U26: =T26 -> 0.087308369 | V26: =(R26-T26)*100 -> -0.097164532 | W26: =W9/$E$3 -> 0.024845475 | X26: =W26 -> 0.024845475 | Y26: =Y9/$G$3 -> 0.011432566 | Z26: =Y26 -> 0.011432566 | AA26: =(W26-Y26)*100 -> 1.3412909 | AB26: =AB9/$E$3 -> 0.057512287 | AC26: =AB26 -> 0.057512287 | AD26: =AD9/$G$3 -> 0.036828605 | AE26: =AD26 -> 0.036828605 | AF26: =(AB26-AD26)*100 -> 2.0683682 | AJ26: =AJ9/$E$3 -> 0.10447314 | AK26: =AJ26 -> 0.10447314 | AL26: =AL9/$G$3 -> 0.087650098 | AM26: =AL26 -> 0.087650098 | AN26: =(AJ26-AL26)*100 -> 1.682304

Sheet SalesOverview
E1: 税率 | F1: 1.13 | G1: 汇率 | H1: 8.19608 | J1: CURDATE | K1: 45992
E2: PFS含税 | AO2: PFS去税
E3: DATE | F3: GMV | G3: NET | H3: UV | I3: Buyers | J3: Units | K3: CR | L3: ATV | M3: AUR | N3: UPT | O3: RRC | P3: RR | Q3: MD GMV | R3: MD GMV % | S3: MD NET | T3: MD NET% | U3: GMV_TGT | V3: NET_TGT | W3: TRAFFIC_TGT | X3: BUYERS_TGT | Y3: CVR_TGT | Z3: ATV_TGT | AA3: UPT_TGT | AB3: RRC_TGT | AC3: UNITS_TGT | AD3: GMV_ACH | AE3: NET_ACH | AF3: TRAFFIC_ACH | AG3: BUYERS_ACH | AH3: CVR_ACH | AI3: ATV_ACH | AJ3: UPT_ACH | AK3: RRC_ACH | AL3: PayYear | AO3: DATE | AP3: GMV | AQ3: NET | AR3: UV | AS3: Buyers | AT3: Units | AU3: CR | AV3: ATV | AW3: AUR | AX3: UPT | AY3: RRC | AZ3: RR | BA3: MD GMV | BB3: MD% | BC3: GMV_TGT | BD3: NET_TGT | BE3: TRAFFIC_TGT | BF3: BUYERS_TGT | BG3: CVR_TGT | BH3: ATV_TGT | BI3: UPT_TGT | BJ3: RRC_TGT | BK3: UNITS_TGT | BL3: PayYear
E4: BU26 | F4: =SUMIFS(PFS_SalesOverview_InTax[GMV],PFS_SalesOverview_InTax[DATE],"<"&EOMONTH($K$1,0)+1,PFS_SalesOverview_InTax[PayYear],PFS_SalesOverview_InTax[[#This Row],[DATE]]) -> 38241499 | G4: =SUMIFS(PFS_SalesOverview_InTax[NET],PFS_SalesOverview_InTax[DATE],"<"&EOMONTH($K$1,0)+1,PFS_SalesOverview_InTax[PayYear],PFS_SalesOverview_InTax[[#This Row],[DATE]]) -> 16357973 | H4: =SUMIFS(PFS_SalesOverview_InTax[UV],PFS_SalesOverview_InTax[DATE],"<"&EOMONTH($K$1,0)+1,PFS_SalesOverview_InTax[PayYear],PFS_SalesOverview_InTax[[#This Row],[DATE]]) -> 4035627 | I4: =SUMIFS(PFS_SalesOverview_InTax[Buyers],PFS_SalesOverview_InTax[DATE],"<"&EOMONTH($K$1,0)+1,PFS_SalesOverview_InTax[PayYear],PFS_SalesOverview_InTax[[#This Row],[DATE]]) -> 7235 | J4: =SUMIFS(PFS_SalesOverview_InTax[Units],PFS_SalesOverview_InTax[DATE],"<"&EOMONTH($K$1,0)+1,PFS_SalesOverview_InTax[PayYear],PFS_SalesOverview_InTax[[#This Row],[DATE]]) -> 10565 | K4: =PFS_SalesOverview_InTax[[#This Row],[Buyers]]/PFS_SalesOverview_InTax[[#This Row],[UV]] -> 0.0017927821 | L4: =PFS_SalesOverview_InTax[[#This Row],[GMV]]/PFS_SalesOverview_InTax[[#This Row],[Buyers]] -> 5285.6252 | M4: =PFS_SalesOverview_InTax[[#This Row],[GMV]]/PFS_SalesOverview_InTax[[#This Row],[Units]] -> 3619.6402 | N4: =PFS_SalesOverview_InTax[[#This Row],[Units]]/PFS_SalesOverview_InTax[[#This Row],[Buyers]] -> 1.4602626 | O4: =PFS_SalesOverview_InTax[[#This Row],[RR]]/PFS_SalesOverview_InTax[[#This Row],[GMV]] -> 0.57224551 | P4: =SUMIFS(PFS_SalesOverview_InTax[RR],PFS_SalesOverview_InTax[PayYear],PFS_SalesOverview_InTax[[#This Row],[DATE]]) -> 21883526 | Q4: =SUMIFS(PFS_SalesOverview_InTax[MD GMV],PFS_SalesOverview_InTax[PayYear],PFS_SalesOverview_InTax[[#This Row],[DATE]]) -> 22303072 | R4: =PFS_SalesOverview_InTax[[#This Row],[MD GMV]]/PFS_SalesOverview_InTax[[#This Row],[GMV]] -> 0.58321648 | S4: =SUMIFS(PFS_SalesOverview_InTax[MD NET],PFS_SalesOverview_InTax[PayYear],PFS_SalesOverview_InTax[[#This Row],[DATE]]) -> 9432897.3 | T4: =PFS_SalesOverview_InTax[[#This Row],[MD NET]]/PFS_SalesOverview_InTax[[#This Row],[NET]] -> 0.57665441 | U4: =SUMIFS(PFS_SalesOverview_InTax[GMV_TGT],PFS_SalesOverview_InTax[DATE],"<"&EOMONTH($K$1,0)+1,PFS_SalesOverview_InTax[PayYear],PFS_SalesOverview_InTax[[#This Row],[DATE]]) -> 45673116 | V4: =SUMIFS(PFS_SalesOverview_InTax[NET_TGT],PFS_SalesOverview_InTax[DATE],"<"&EOMONTH($K$1,0)+1,PFS_SalesOverview_InTax[PayYear],PFS_SalesOverview_InTax[[#This Row],[DATE]]) -> 19251771 | W4: =SUMIFS(PFS_SalesOverview_InTax[TRAFFIC_TGT],PFS_SalesOverview_InTax[DATE],"<"&EOMONTH($K$1,0)+1,PFS_SalesOverview_InTax[PayYear],PFS_SalesOverview_InTax[[#This Row],[DATE]]) -> 4867521 | X4: =SUMIFS(PFS_SalesOverview_InTax[BUYERS_TGT],PFS_SalesOverview_InTax[DATE],"<"&EOMONTH($K$1,0)+1,PFS_SalesOverview_InTax[PayYear],PFS_SalesOverview_InTax[[#This Row],[DATE]]) -> 10441 | Y4: =PFS_SalesOverview_InTax[[#This Row],[BUYERS_TGT]]/PFS_SalesOverview_InTax[[#This Row],[TRAFFIC_TGT]] -> 0.0021450344 | Z4: =PFS_SalesOverview_InTax[[#This Row],[GMV_TGT]]/PFS_SalesOverview_InTax[[#This Row],[BUYERS_TGT]] -> 4374.4005 | AA4: =PFS_SalesOverview_InTax[[#This Row],[UNITS_TGT]]/PFS_SalesOverview_InTax[[#This Row],[BUYERS_TGT]] -> 1.2006513 | AB4: =1-PFS_SalesOverview_InTax[[#This Row],[NET_TGT]]/PFS_SalesOverview_InTax[[#This Row],[GMV_TGT]] -> 0.5784879 | AC4: =SUMIFS(PFS_SalesOverview_InTax[UNITS_TGT],PFS_SalesOverview_InTax[DATE],"<"&EOMONTH($K$1,0)+1,PFS_SalesOverview_InTax[PayYear],PFS_SalesOverview_InTax[[#This Row],[DATE]]) -> 12536 | AD4: =PFS_SalesOverview_InTax[[#This Row],[GMV]]/PFS_SalesOverview_InTax[[#This Row],[GMV_TGT]] -> 0.83728683 | AE4: =PFS_SalesOverview_InTax[[#This Row],[NET]]/PFS_SalesOverview_InTax[[#This Row],[NET_TGT]] -> 0.84968666 | AF4: =PFS_SalesOverview_InTax[[#This Row],[UV]]/PFS_SalesOverview_InTax[[#This Row],[TRAFFIC_TGT]] -> 0.82909288 | AG4: =PFS_SalesOverview_InTax[[#This Row],[Buyers]]/PFS_SalesOverview_InTax[[#This Row],[BUYERS_TGT]] -> 0.69294129 | AH4: =PFS_SalesOverview_InTax[[#This Row],[CR]]/PFS_SalesOverview_InTax[[#This Row],[CVR_TGT]] -> 0.83578246 | AI4: =PFS_SalesOverview_InTax[[#This Row],[ATV]]/PFS_SalesOverview_InTax[[#This Row],[ATV_TGT]] -> 1.2083085 | AJ4: =PFS_SalesOverview_InTax[[#This Row],[UPT]]/PFS_SalesOverview_InTax[[#This Row],[UPT_TGT]] -> 1.2162254 | AK4: =PFS_SalesOverview_InTax[[#This Row],[RRC]]/PFS_SalesOverview_InTax[[#This Row],[RRC_TGT]] -> 0.98920912 | AL4: =_xlfn.XLOOKUP(PFS_SalesOverview_InTax[[#This Row],[DATE]],全店核心数据_bymonth[开始日期],全店核心数据_bymonth[jda日历.PayYear],"") | AO4: =PFS_SalesOverview_InTax[[#This Row],[DATE]] -> BU26 | AP4: =PFS_SalesOverview_InTax[[#This Row],[GMV]]/$F$1 -> 33842034 | AQ4: =PFS_SalesOverview_ExclTax[[#This Row],[GMV]]-PFS_SalesOverview_ExclTax[[#This Row],[RR]] -> 14476082 | AR4: =PFS_SalesOverview_InTax[[#This Row],[UV]] -> 4035627 | AS4: =PFS_SalesOverview_InTax[[#This Row],[Buyers]] -> 7235 | AT4: =PFS_SalesOverview_InTax[[#This Row],[Units]] -> 10565 | AU4: =PFS_SalesOverview_ExclTax[[#This Row],[Buyers]]/PFS_SalesOverview_ExclTax[[#This Row],[UV]] -> 0.0017927821 | AV4: =PFS_SalesOverview_ExclTax[[#This Row],[GMV]]/PFS_SalesOverview_ExclTax[[#This Row],[Buyers]] -> 4677.5445 | AW4: =PFS_SalesOverview_ExclTax[[#This Row],[GMV]]/PFS_SalesOverview_ExclTax[[#This Row],[Units]] -> 3203.2214 | AX4: =PFS_SalesOverview_ExclTax[[#This Row],[Units]]/PFS_SalesOverview_ExclTax[[#This Row],[Buyers]] -> 1.4602626 | AY4: =PFS_SalesOverview_ExclTax[[#This Row],[RR]]/PFS_SalesOverview_ExclTax[[#This Row],[GMV]] -> 0.57224551 | AZ4: =PFS_SalesOverview_InTax[[#This Row],[RR]]/$F$1 -> 19365952 | BA4: =PFS_SalesOverview_InTax[[#This Row],[MD GMV]]/$F$1 -> 19737232 | BB4: =PFS_SalesOverview_ExclTax[[#This Row],[MD GMV]]/PFS_SalesOverview_ExclTax[[#This Row],[GMV]] -> 0.58321648 | BC4: =PFS_SalesOverview_InTax[[#This Row],[GMV_TGT]]/$F$1 -> 40418687 | BD4: =PFS_SalesOverview_InTax[[#This Row],[NET_TGT]]/$F$1 -> 17036965 | BE4: =PFS_SalesOverview_InTax[[#This Row],[TRAFFIC_TGT]] -> 4867521 | BF4: =PFS_SalesOverview_InTax[[#This Row],[BUYERS_TGT]] -> 10441 | BG4: =PFS_SalesOverview_InTax[[#This Row],[CVR_TGT]] -> 0.0021450344 | BH4: =PFS_SalesOverview_InTax[[#This Row],[ATV_TGT]]/$F$1 -> 3871.1509 | BI4: =PFS_SalesOverview_InTax[[#This Row],[UPT_TGT]] -> 1.2006513 | BJ4: =PFS_SalesOverview_InTax[[#This Row],[RRC_TGT]] -> 0.5784879 | BK4: =PFS_SalesOverview_InTax[[#This Row],[UNITS_TGT]] -> 12536 | BL4: =_xlfn.XLOOKUP(PFS_SalesOverview_ExclTax[[#This Row],[DATE]],全店核心数据_bymonth[开始日期],全店核心数据_bymonth[jda日历.PayYear],"")
E5: BU25 | F5: =SUMIFS(PFS_SalesOverview_InTax[GMV],PFS_SalesOverview_InTax[DATE],"<"&EDATE(EOMONTH($K$1,0)+1,-12),PFS_SalesOverview_InTax[PayYear],PFS_SalesOverview_InTax[[#This Row],[DATE]]) -> 49008972 | G5: =SUMIFS(PFS_SalesOverview_InTax[NET],PFS_SalesOverview_InTax[DATE],"<"&EDATE(EOMONTH($K$1,0)+1,-12),PFS_SalesOverview_InTax[PayYear],PFS_SalesOverview_InTax[[#This Row],[DATE]]) -> 17277262 | H5: =SUMIFS(PFS_SalesOverview_InTax[UV],PFS_SalesOverview_InTax[DATE],"<"&EDATE(EOMONTH($K$1,0)+1,-12),PFS_SalesOverview_InTax[PayYear],PFS_SalesOverview_InTax[[#This Row],[DATE]]) -> 3164908 | I5: =SUMIFS(PFS_SalesOverview_InTax[Buyers],PFS_SalesOverview_InTax[DATE],"<"&EDATE(EOMONTH($K$1,0)+1,-12),PFS_SalesOverview_InTax[PayYear],PFS_SalesOverview_InTax[[#This Row],[DATE]]) -> 9696 | J5: =SUMIFS(PFS_SalesOverview_InTax[Units],PFS_SalesOverview_InTax[DATE],"<"&EDATE(EOMONTH($K$1,0)+1,-12),PFS_SalesOverview_InTax[PayYear],PFS_SalesOverview_InTax[[#This Row],[DATE]]) -> 14163 | K5: =PFS_SalesOverview_InTax[[#This Row],[Buyers]]/PFS_SalesOverview_InTax[[#This Row],[UV]] -> 0.0030635962 | L5: =PFS_SalesOverview_InTax[[#This Row],[GMV]]/PFS_SalesOverview_InTax[[#This Row],[Buyers]] -> 5054.5556 | M5: =PFS_SalesOverview_InTax[[#This Row],[GMV]]/PFS_SalesOverview_InTax[[#This Row],[Units]] -> 3460.3524 | N5: =PFS_SalesOverview_InTax[[#This Row],[Units]]/PFS_SalesOverview_InTax[[#This Row],[Buyers]] -> 1.4607054 | O5: =PFS_SalesOverview_InTax[[#This Row],[RR]]/PFS_SalesOverview_InTax[[#This Row],[GMV]] -> 0.64746736 | P5: =SUMIFS(PFS_SalesOverview_InTax[RR],PFS_SalesOverview_InTax[DATE],"<"&EDATE(EOMONTH($K$1,0)+1,-12),PFS_SalesOverview_InTax[PayYear],PFS_SalesOverview_InTax[[#This Row],[DATE]]) -> 31731709 | Q5: =SUMIFS(PFS_SalesOverview_InTax[MD GMV],PFS_SalesOverview_InTax[DATE],"<"&EDATE(EOMONTH($K$1,0)+1,-12),PFS_SalesOverview_InTax[PayYear],PFS_SalesOverview_InTax[[#This Row],[DATE]]) -> 33201289 | R5: =PFS_SalesOverview_InTax[[#This Row],[MD GMV]]/PFS_SalesOverview_InTax[[#This Row],[GMV]] -> 0.6774533 | S5: =SUMIFS(PFS_SalesOverview_InTax[MD NET],PFS_SalesOverview_InTax[DATE],"<"&EDATE(EOMONTH($K$1,0)+1,-12),PFS_SalesOverview_InTax[PayYear],PFS_SalesOverview_InTax[[#This Row],[DATE]]) -> 11114831 | T5: =PFS_SalesOverview_InTax[[#This Row],[MD NET]]/PFS_SalesOverview_InTax[[#This Row],[NET]] -> 0.64332128 | U5: =SUMIFS(PFS_SalesOverview_InTax[GMV_TGT],PFS_SalesOverview_InTax[DATE],"<"&EDATE(EOMONTH($K$1,0)+1,-12),PFS_SalesOverview_InTax[PayYear],PFS_SalesOverview_InTax[[#This Row],[DATE]]) -> 50650479 | V5: =SUMIFS(PFS_SalesOverview_InTax[NET_TGT],PFS_SalesOverview_InTax[DATE],"<"&EDATE(EOMONTH($K$1,0)+1,-12),PFS_SalesOverview_InTax[PayYear],PFS_SalesOverview_InTax[[#This Row],[DATE]]) -> 19572320 | W5: =SUMIFS(PFS_SalesOverview_InTax[TRAFFIC_TGT],PFS_SalesOverview_InTax[DATE],"<"&EDATE(EOMONTH($K$1,0)+1,-12),PFS_SalesOverview_InTax[PayYear],PFS_SalesOverview_InTax[[#This Row],[DATE]]) -> 4156844 | X5: =SUMIFS(PFS_SalesOverview_InTax[BUYERS_TGT],PFS_SalesOverview_InTax[DATE],"<"&EDATE(EOMONTH($K$1,0)+1,-12),PFS_SalesOverview_InTax[PayYear],PFS_SalesOverview_InTax[[#This Row],[DATE]]) -> 11374 | Y5: =PFS_SalesOverview_InTax[[#This Row],[BUYERS_TGT]]/PFS_SalesOverview_InTax[[#This Row],[TRAFFIC_TGT]] -> 0.0027362105 | Z5: =PFS_SalesOverview_InTax[[#This Row],[GMV_TGT]]/PFS_SalesOverview_InTax[[#This Row],[BUYERS_TGT]] -> 4453.1809 | AA5: =PFS_SalesOverview_InTax[[#This Row],[UNITS_TGT]]/PFS_SalesOverview_InTax[[#This Row],[BUYERS_TGT]] -> 1.3046422 | AB5: =1-PFS_SalesOverview_InTax[[#This Row],[NET_TGT]]/PFS_SalesOverview_InTax[[#This Row],[GMV_TGT]] -> 0.61358075 | AC5: =SUMIFS(PFS_SalesOverview_InTax[UNITS_TGT],PFS_SalesOverview_InTax[DATE],"<"&EDATE(EOMONTH($K$1,0)+1,-12),PFS_SalesOverview_InTax[PayYear],PFS_SalesOverview_InTax[[#This Row],[DATE]]) -> 14839 | AD5: =PFS_SalesOverview_InTax[[#This Row],[GMV]]/PFS_SalesOverview_InTax[[#This Row],[GMV_TGT]] -> 0.96759147 | AE5: =PFS_SalesOverview_InTax[[#This Row],[NET]]/PFS_SalesOverview_InTax[[#This Row],[NET_TGT]] -> 0.88273962 | AF5: =PFS_SalesOverview_InTax[[#This Row],[UV]]/PFS_SalesOverview_InTax[[#This Row],[TRAFFIC_TGT]] -> 0.76137281 | AG5: =PFS_SalesOverview_InTax[[#This Row],[Buyers]]/PFS_SalesOverview_InTax[[#This Row],[BUYERS_TGT]] -> 0.85247055 | AH5: =PFS_SalesOverview_InTax[[#This Row],[CR]]/PFS_SalesOverview_InTax[[#This Row],[CVR_TGT]] -> 1.1196493 | AI5: =PFS_SalesOverview_InTax[[#This Row],[ATV]]/PFS_SalesOverview_InTax[[#This Row],[ATV_TGT]] -> 1.1350439 | AJ5: =PFS_SalesOverview_InTax[[#This Row],[UPT]]/PFS_SalesOverview_InTax[[#This Row],[UPT_TGT]] -> 1.1196215 | AK5: =PFS_SalesOverview_InTax[[#This Row],[RRC]]/PFS_SalesOverview_InTax[[#This Row],[RRC_TGT]] -> 1.0552276 | AL5: =_xlfn.XLOOKUP(PFS_SalesOverview_InTax[[#This Row],[DATE]],全店核心数据_bymonth[开始日期],全店核心数据_bymonth[jda日历.PayYear],"") | AO5: =PFS_SalesOverview_InTax[[#This Row],[DATE]] -> BU25 | AP5: =PFS_SalesOverview_InTax[[#This Row],[GMV]]/$F$1 -> 43370771 | AQ5: =PFS_SalesOverview_ExclTax[[#This Row],[GMV]]-PFS_SalesOverview_ExclTax[[#This Row],[RR]] -> 15289613 | AR5: =PFS_SalesOverview_InTax[[#This Row],[UV]] -> 3164908 | AS5: =PFS_SalesOverview_InTax[[#This Row],[Buyers]] -> 9696 | AT5: =PFS_SalesOverview_InTax[[#This Row],[Units]] -> 14163 | AU5: =PFS_SalesOverview_ExclTax[[#This Row],[Buyers]]/PFS_SalesOverview_ExclTax[[#This Row],[UV]] -> 0.0030635962 | AV5: =PFS_SalesOverview_ExclTax[[#This Row],[GMV]]/PFS_SalesOverview_ExclTax[[#This Row],[Buyers]] -> 4473.0581 | AW5: =PFS_SalesOverview_ExclTax[[#This Row],[GMV]]/PFS_SalesOverview_ExclTax[[#This Row],[Units]] -> 3062.2588 | AX5: =PFS_SalesOverview_ExclTax[[#This Row],[Units]]/PFS_SalesOverview_ExclTax[[#This Row],[Buyers]] -> 1.4607054 | AY5: =PFS_SalesOverview_ExclTax[[#This Row],[RR]]/PFS_SalesOverview_ExclTax[[#This Row],[GMV]] -> 0.64746736 | AZ5: =PFS_SalesOverview_InTax[[#This Row],[RR]]/$F$1 -> 28081159 | BA5: =PFS_SalesOverview_InTax[[#This Row],[MD GMV]]/$F$1 -> 29381672 | BB5: =PFS_SalesOverview_ExclTax[[#This Row],[MD GMV]]/PFS_SalesOverview_ExclTax[[#This Row],[GMV]] -> 0.6774533 | BC5: =PFS_SalesOverview_InTax[[#This Row],[GMV_TGT]]/$F$1 -> 44823433 | BD5: =PFS_SalesOverview_InTax[[#This Row],[NET_TGT]]/$F$1 -> 17320637 | BE5: =PFS_SalesOverview_InTax[[#This Row],[TRAFFIC_TGT]] -> 4156844 | BF5: =PFS_SalesOverview_InTax[[#This Row],[BUYERS_TGT]] -> 11374 | BG5: =PFS_SalesOverview_InTax[[#This Row],[CVR_TGT]] -> 0.0027362105 | BH5: =PFS_SalesOverview_InTax[[#This Row],[ATV_TGT]]/$F$1 -> 3940.868 | BI5: =PFS_SalesOverview_InTax[[#This Row],[UPT_TGT]] -> 1.3046422 | BJ5: =PFS_SalesOverview_InTax[[#This Row],[RRC_TGT]] -> 0.61358075 | BK5: =PFS_SalesOverview_InTax[[#This Row],[UNITS_TGT]] -> 14839 | BL5: =_xlfn.XLOOKUP(PFS_SalesOverview_ExclTax[[#This Row],[DATE]],全店核心数据_bymonth[开始日期],全店核心数据_bymonth[jda日历.PayYear],"")
E6: YOY | F6: =F4/F5-1 -> -0.21970412 | G6: =G4/G5-1 -> -0.053208043 | H6: =H4/H5-1 -> 0.27511669 | I6: =I4/I5-1 -> -0.25381601 | J6: =J4/J5-1 -> -0.25404222 | K6: =K4/K5-1 -> -0.41481121 | L6: =L4/L5-1 -> 0.045715117 | M6: =M4/M5-1 -> 0.046032236 | N6: =N4/N5-1 -> -0.00030316396 | O6: =(O4-O5)*100 -> -7.5221852 | P6: =P4/P5-1 -> -0.3103578 | Q6: =Q4/Q5-1 -> -0.3282468 | R6: =(R4-R5)*100 -> -9.4236816 | S6: =S4/S5-1 -> -0.15132334 | T6: =(T4-T5)*100 -> -6.666687 | U6: =U4/U5-1 -> -0.098268824 | V6: =V4/V5-1 -> -0.01637767 | W6: =W4/W5-1 -> 0.17096552 | X6: =X4/X5-1 -> -0.082029189 | Y6: =Y4/Y5-1 -> -0.2160565 | Z6: =Z4/Z5-1 -> -0.017690796 | AA6: =AA4/AA5-1 -> -0.07970836 | AB6: =(AB4-AB5)*100 -> -3.5092851 | AC6: =AC4/AC5-1 -> -0.15519914 | AD6: =(AD4-AD5)*100 -> -13.030464 | AE6: =(AE4-AE5)*100 -> -3.305296 | AF6: =(AF4-AF5)*100 -> 6.7720068 | AG6: =(AG4-AG5)*100 -> -15.952926 | AH6: =(AH4-AH5)*100 -> -28.386685 | AI6: =(AI4-AI5)*100 -> 7.3264602 | AJ6: =(AJ4-AJ5)*100 -> 9.6603905 | AK6: =(AK4-AK5)*100 -> -6.6018505 | AL6: =_xlfn.XLOOKUP(PFS_SalesOverview_InTax[[#This Row],[DATE]],全店核心数据_bymonth[开始日期],全店核心数据_bymonth[jda日历.PayYear],"") | AO6: =PFS_SalesOverview_InTax[[#This Row],[DATE]] -> YOY | AP6: =AP4/AP5-1 -> -0.21970412 | AQ6: =AQ4/AQ5-1 -> -0.053208043 | AR6: =AR4/AR5-1 -> 0.27511669 | AS6: =AS4/AS5-1 -> -0.25381601 | AT6: =AT4/AT5-1 -> -0.25404222 | AU6: =AU4/AU5-1 -> -0.41481121 | AV6: =AV4/AV5-1 -> 0.045715117 | AW6: =AW4/AW5-1 -> 0.046032236 | AX6: =AX4/AX5-1 -> -0.00030316396 | AY6: =(AY4-AY5)*100 -> -7.5221852 | AZ6: =AZ4/AZ5-1 -> -0.3103578 | BA6: =BA4/BA5-1 -> -0.3282468 | BB6: =(BB4-BB5)*100 -> -9.4236816 | BL6: =_xlfn.XLOOKUP(PFS_SalesOverview_ExclTax[[#This Row],[DATE]],全店核心数据_bymonth[开始日期],全店核心数据_bymonth[jda日历.PayYear],"")
E7: 45992 | F7: =SUMIFS(全店核心数据_bymonth[支付金额],全店核心数据_bymonth[开始日期],$E7) -> 5693669 | G7: =PFS_SalesOverview_InTax[[#This Row],[GMV]]-PFS_SalesOverview_InTax[[#This Row],[RR]] -> 2418883.6 | H7: =SUMIFS(全店核心数据_bymonth[访客数],全店核心数据_bymonth[开始日期],$E7) -> 533249 | I7: =SUMIFS(全店核心数据_bymonth[支付买家数],全店核心数据_bymonth[开始日期],$E7) -> 914 | J7: =SUMIFS(全店核心数据_bymonth[支付件数],全店核心数据_bymonth[开始日期],$E7) -> 1310 | K7: =PFS_SalesOverview_InTax[[#This Row],[Buyers]]/PFS_SalesOverview_InTax[[#This Row],[UV]] -> 0.001714021 | L7: =PFS_SalesOverview_InTax[[#This Row],[GMV]]/PFS_SalesOverview_InTax[[#This Row],[Buyers]] -> 6229.3972 | M7: =PFS_SalesOverview_InTax[[#This Row],[GMV]]/PFS_SalesOverview_InTax[[#This Row],[Units]] -> 4346.3122 | N7: =PFS_SalesOverview_InTax[[#This Row],[Units]]/PFS_SalesOverview_InTax[[#This Row],[Buyers]] -> 1.4332604 | O7: =PFS_SalesOverview_InTax[[#This Row],[RR]]/PFS_SalesOverview_InTax[[#This Row],[GMV]] -> 0.57516259 | P7: =SUMIFS(全店核心数据_bymonth[支付退款金额],全店核心数据_bymonth[开始日期],$E7) -> 3274785.4 | Q7: =SUMIFS(全店核心数据_bymonth[md_gmv],全店核心数据_bymonth[开始日期],$E7) -> 3911164.9 | R7: =PFS_SalesOverview_InTax[[#This Row],[MD GMV]]/PFS_SalesOverview_InTax[[#This Row],[GMV]] -> 0.68693226 | S7: =SUMIFS(全店核心数据_bymonth[md_net],全店核心数据_bymonth[开始日期],$E7) -> 1499568.6 | T7: =PFS_SalesOverview_InTax[[#This Row],[MD NET]]/PFS_SalesOverview_InTax[[#This Row],[NET]] -> 0.61994242 | U7: =SUMIFS(目标表[gmv],目标表[Date],">="&$E7,目标表[Date],"<="&EOMONTH($E7,0),目标表[channel],"PFS") -> 5800000 | V7: =SUMIFS(目标表[net],目标表[Date],">="&$E7,目标表[Date],"<="&EOMONTH($E7,0),目标表[channel],"PFS") -> 2900000 | W7: =SUMIFS(目标表[uv],目标表[Date],">="&$E7,目标表[Date],"<="&EOMONTH($E7,0),目标表[channel],"PFS") -> 394279 | X7: =SUMIFS(目标表[buyers],目标表[Date],">="&$E7,目标表[Date],"<="&EOMONTH($E7,0),目标表[channel],"PFS") -> 1133 | Y7: =PFS_SalesOverview_InTax[[#This Row],[BUYERS_TGT]]/PFS_SalesOverview_InTax[[#This Row],[TRAFFIC_TGT]] -> 0.0028735997 | Z7: =PFS_SalesOverview_InTax[[#This Row],[GMV_TGT]]/PFS_SalesOverview_InTax[[#This Row],[BUYERS_TGT]] -> 5119.1527 | AA7: =PFS_SalesOverview_InTax[[#This Row],[UNITS_TGT]]/PFS_SalesOverview_InTax[[#This Row],[BUYERS_TGT]] -> 1.3009709 | AB7: =1-PFS_SalesOverview_InTax[[#This Row],[NET_TGT]]/PFS_SalesOverview_InTax[[#This Row],[GMV_TGT]] -> 0.5 | AC7: =SUMIFS(目标表[gmv_units],目标表[Date],">="&$E7,目标表[Date],"<="&EOMONTH($E7,0),目标表[channel],"PFS") -> 1474 | AD7: =PFS_SalesOverview_InTax[[#This Row],[GMV]]/PFS_SalesOverview_InTax[[#This Row],[GMV_TGT]] -> 0.98166707 | AE7: =PFS_SalesOverview_InTax[[#This Row],[NET]]/PFS_SalesOverview_InTax[[#This Row],[NET_TGT]] -> 0.83409779 | AF7: =PFS_SalesOverview_InTax[[#This Row],[UV]]/PFS_SalesOverview_InTax[[#This Row],[TRAFFIC_TGT]] -> 1.3524661 | AG7: =PFS_SalesOverview_InTax[[#This Row],[Buyers]]/PFS_SalesOverview_InTax[[#This Row],[BUYERS_TGT]] -> 0.80670786 | AH7: =PFS_SalesOverview_InTax[[#This Row],[CR]]/PFS_SalesOverview_InTax[[#This Row],[CVR_TGT]] -> 0.59647175 | AI7: =PFS_SalesOverview_InTax[[#This Row],[ATV]]/PFS_SalesOverview_InTax[[#This Row],[ATV_TGT]] -> 1.2168805 | AJ7: =PFS_SalesOverview_InTax[[#This Row],[UPT]]/PFS_SalesOverview_InTax[[#This Row],[UPT_TGT]] -> 1.1016852 | AK7: =PFS_SalesOverview_InTax[[#This Row],[RRC]]/PFS_SalesOverview_InTax[[#This Row],[RRC_TGT]] -> 1.1503252 | AL7: =_xlfn.XLOOKUP(PFS_SalesOverview_InTax[[#This Row],[DATE]],全店核心数据_bymonth[开始日期],全店核心数据_bymonth[jda日历.PayYear],"") -> BU26 | AO7: =PFS_SalesOverview_InTax[[#This Row],[DATE]] -> 45992 | AP7: =PFS_SalesOverview_InTax[[#This Row],[GMV]]/$F$1 -> 5038645.1 | AQ7: =PFS_SalesOverview_ExclTax[[#This Row],[GMV]]-PFS_SalesOverview_ExclTax[[#This Row],[RR]] -> 2140604.9 | AR7: =PFS_SalesOverview_InTax[[#This Row],[UV]] -> 533249 | AS7: =PFS_SalesOverview_InTax[[#This Row],[Buyers]] -> 914 | AT7: =PFS_SalesOverview_InTax[[#This Row],[Units]] -> 1310 | AU7: =PFS_SalesOverview_ExclTax[[#This Row],[Buyers]]/PFS_SalesOverview_ExclTax[[#This Row],[UV]] -> 0.001714021 | AV7: =PFS_SalesOverview_ExclTax[[#This Row],[GMV]]/PFS_SalesOverview_ExclTax[[#This Row],[Buyers]] -> 5512.7408 | AW7: =PFS_SalesOverview_ExclTax[[#This Row],[GMV]]/PFS_SalesOverview_ExclTax[[#This Row],[Units]] -> 3846.294 | AX7: =PFS_SalesOverview_ExclTax[[#This Row],[Units]]/PFS_SalesOverview_ExclTax[[#This Row],[Buyers]] -> 1.4332604 | AY7: =PFS_SalesOverview_ExclTax[[#This Row],[RR]]/PFS_SalesOverview_ExclTax[[#This Row],[GMV]] -> 0.57516259 | AZ7: =PFS_SalesOverview_InTax[[#This Row],[RR]]/$F$1 -> 2898040.2 | BA7: =PFS_SalesOverview_InTax[[#This Row],[MD GMV]]/$F$1 -> 3461207.9 | BB7: =PFS_SalesOverview_ExclTax[[#This Row],[MD GMV]]/PFS_SalesOverview_ExclTax[[#This Row],[GMV]] -> 0.68693226 | BC7: =PFS_SalesOverview_InTax[[#This Row],[GMV_TGT]]/$F$1 -> 5132743.4 | BD7: =PFS_SalesOverview_InTax[[#This Row],[NET_TGT]]/$F$1 -> 2566371.7 | BE7: =PFS_SalesOverview_InTax[[#This Row],[TRAFFIC_TGT]] -> 394279 | BF7: =PFS_SalesOverview_InTax[[#This Row],[BUYERS_TGT]] -> 1133 | BG7: =PFS_SalesOverview_InTax[[#This Row],[CVR_TGT]] -> 0.0028735997 | BH7: =PFS_SalesOverview_InTax[[#This Row],[ATV_TGT]]/$F$1 -> 4530.2236 | BI7: =PFS_SalesOverview_InTax[[#This Row],[UPT_TGT]] -> 1.3009709 | BJ7: =PFS_SalesOverview_InTax[[#This Row],[RRC_TGT]] -> 0.5 | BK7: =PFS_SalesOverview_InTax[[#This Row],[UNITS_TGT]] -> 1474 | BL7: =_xlfn.XLOOKUP(PFS_SalesOverview_ExclTax[[#This Row],[DATE]],全店核心数据_bymonth[开始日期],全店核心数据_bymonth[jda日历.PayYear],"") -> BU26
E8: 45962 | F8: =SUMIFS(全店核心数据_bymonth[支付金额],全店核心数据_bymonth[开始日期],$E8) -> 6161292.2 | G8: =PFS_SalesOverview_InTax[[#This Row],[GMV]]-PFS_SalesOverview_InTax[[#This Row],[RR]] -> 2660913.8 | H8: =SUMIFS(全店核心数据_bymonth[访客数],全店核心数据_bymonth[开始日期],$E8) -> 576288 | I8: =SUMIFS(全店核心数据_bymonth[支付买家数],全店核心数据_bymonth[开始日期],$E8) -> 1059 | J8: =SUMIFS(全店核心数据_bymonth[支付件数],全店核心数据_bymonth[开始日期],$E8) -> 1546 | K8: =PFS_SalesOverview_InTax[[#This Row],[Buyers]]/PFS_SalesOverview_InTax[[#This Row],[UV]] -> 0.0018376229 | L8: =PFS_SalesOverview_InTax[[#This Row],[GMV]]/PFS_SalesOverview_InTax[[#This Row],[Buyers]] -> 5818.0285 | M8: =PFS_SalesOverview_InTax[[#This Row],[GMV]]/PFS_SalesOverview_InTax[[#This Row],[Units]] -> 3985.3119 | N8: =PFS_SalesOverview_InTax[[#This Row],[Units]]/PFS_SalesOverview_InTax[[#This Row],[Buyers]] -> 1.4598678 | O8: =PFS_SalesOverview_InTax[[#This Row],[RR]]/PFS_SalesOverview_InTax[[#This Row],[GMV]] -> 0.56812408 | P8: =SUMIFS(全店核心数据_bymonth[支付退款金额],全店核心数据_bymonth[开始日期],$E8) -> 3500378.5 | Q8: =SUMIFS(全店核心数据_bymonth[md_gmv],全店核心数据_bymonth[开始日期],$E8) -> 4316592.2 | R8: =PFS_SalesOverview_InTax[[#This Row],[MD GMV]]/PFS_SalesOverview_InTax[[#This Row],[GMV]] -> 0.70059851 | S8: =SUMIFS(全店核心数据_bymonth[md_net],全店核心数据_bymonth[开始日期],$E8) -> 1798700.6 | T8: =PFS_SalesOverview_InTax[[#This Row],[MD NET]]/PFS_SalesOverview_InTax[[#This Row],[NET]] -> 0.675971 | U8: =SUMIFS(目标表[gmv],目标表[Date],">="&$E8,目标表[Date],"<="&EOMONTH($E8,0),目标表[channel],"PFS") -> 8840000 | V8: =SUMIFS(目标表[net],目标表[Date],">="&$E8,目标表[Date],"<="&EOMONTH($E8,0),目标表[channel],"PFS") -> 3690000 | W8: =SUMIFS(目标表[uv],目标表[Date],">="&$E8,目标表[Date],"<="&EOMONTH($E8,0),目标表[channel],"PFS") -> 645869 | X8: =SUMIFS(目标表[buyers],目标表[Date],">="&$E8,目标表[Date],"<="&EOMONTH($E8,0),目标表[channel],"PFS") -> 1894 | Y8: =PFS_SalesOverview_InTax[[#This Row],[BUYERS_TGT]]/PFS_SalesOverview_InTax[[#This Row],[TRAFFIC_TGT]] -> 0.0029324832 | Z8: =PFS_SalesOverview_InTax[[#This Row],[GMV_TGT]]/PFS_SalesOverview_InTax[[#This Row],[BUYERS_TGT]] -> 4667.3706 | AA8: =PFS_SalesOverview_InTax[[#This Row],[UNITS_TGT]]/PFS_SalesOverview_InTax[[#This Row],[BUYERS_TGT]] -> 1.1473073 | AB8: =1-PFS_SalesOverview_InTax[[#This Row],[NET_TGT]]/PFS_SalesOverview_InTax[[#This Row],[GMV_TGT]] -> 0.58257919 | AC8: =SUMIFS(目标表[gmv_units],目标表[Date],">="&$E8,目标表[Date],"<="&EOMONTH($E8,0),目标表[channel],"PFS") -> 2173 | AD8: =PFS_SalesOverview_InTax[[#This Row],[GMV]]/PFS_SalesOverview_InTax[[#This Row],[GMV_TGT]] -> 0.69697876 | AE8: =PFS_SalesOverview_InTax[[#This Row],[NET]]/PFS_SalesOverview_InTax[[#This Row],[NET_TGT]] -> 0.72111484 | AF8: =PFS_SalesOverview_InTax[[#This Row],[UV]]/PFS_SalesOverview_InTax[[#This Row],[TRAFFIC_TGT]] -> 0.89226763 | AG8: =PFS_SalesOverview_InTax[[#This Row],[Buyers]]/PFS_SalesOverview_InTax[[#This Row],[BUYERS_TGT]] -> 0.55913411 | AH8: =PFS_SalesOverview_InTax[[#This Row],[CR]]/PFS_SalesOverview_InTax[[#This Row],[CVR_TGT]] -> 0.62664395 | AI8: =PFS_SalesOverview_InTax[[#This Row],[ATV]]/PFS_SalesOverview_InTax[[#This Row],[ATV_TGT]] -> 1.2465324 | AJ8: =PFS_SalesOverview_InTax[[#This Row],[UPT]]/PFS_SalesOverview_InTax[[#This Row],[UPT_TGT]] -> 1.2724296 | AK8: =PFS_SalesOverview_InTax[[#This Row],[RRC]]/PFS_SalesOverview_InTax[[#This Row],[RRC_TGT]] -> 0.97518774 | AL8: =_xlfn.XLOOKUP(PFS_SalesOverview_InTax[[#This Row],[DATE]],全店核心数据_bymonth[开始日期],全店核心数据_bymonth[jda日历.PayYear],"") -> BU26 | AO8: =PFS_SalesOverview_InTax[[#This Row],[DATE]] -> 45962 | AP8: =PFS_SalesOverview_InTax[[#This Row],[GMV]]/$F$1 -> 5452471 | AQ8: =PFS_SalesOverview_ExclTax[[#This Row],[GMV]]-PFS_SalesOverview_ExclTax[[#This Row],[RR]] -> 2354790.9 | AR8: =PFS_SalesOverview_InTax[[#This Row],[UV]] -> 576288 | AS8: =PFS_SalesOverview_InTax[[#This Row],[Buyers]] -> 1059 | AT8: =PFS_SalesOverview_InTax[[#This Row],[Units]] -> 1546 | AU8: =PFS_SalesOverview_ExclTax[[#This Row],[Buyers]]/PFS_SalesOverview_ExclTax[[#This Row],[UV]] -> 0.0018376229 | AV8: =PFS_SalesOverview_ExclTax[[#This Row],[GMV]]/PFS_SalesOverview_ExclTax[[#This Row],[Buyers]] -> 5148.6978 | AW8: =PFS_SalesOverview_ExclTax[[#This Row],[GMV]]/PFS_SalesOverview_ExclTax[[#This Row],[Units]] -> 3526.8247 | AX8: =PFS_SalesOverview_ExclTax[[#This Row],[Units]]/PFS_SalesOverview_ExclTax[[#This Row],[Buyers]] -> 1.4598678 | AY8: =PFS_SalesOverview_ExclTax[[#This Row],[RR]]/PFS_SalesOverview_ExclTax[[#This Row],[GMV]] -> 0.56812408 | AZ8: =PFS_SalesOverview_InTax[[#This Row],[RR]]/$F$1 -> 3097680.1 | BA8: =PFS_SalesOverview_InTax[[#This Row],[MD GMV]]/$F$1 -> 3819993.1 | BB8: =PFS_SalesOverview_ExclTax[[#This Row],[MD GMV]]/PFS_SalesOverview_ExclTax[[#This Row],[GMV]] -> 0.70059851 | BC8: =PFS_SalesOverview_InTax[[#This Row],[GMV_TGT]]/$F$1 -> 7823008.8 | BD8: =PFS_SalesOverview_InTax[[#This Row],[NET_TGT]]/$F$1 -> 3265486.7 | BE8: =PFS_SalesOverview_InTax[[#This Row],[TRAFFIC_TGT]] -> 645869 | BF8: =PFS_SalesOverview_InTax[[#This Row],[BUYERS_TGT]] -> 1894 | BG8: =PFS_SalesOverview_InTax[[#This Row],[CVR_TGT]] -> 0.0029324832 | BH8: =PFS_SalesOverview_InTax[[#This Row],[ATV_TGT]]/$F$1 -> 4130.4165 | BI8: =PFS_SalesOverview_InTax[[#This Row],[UPT_TGT]] -> 1.1473073 | BJ8: =PFS_SalesOverview_InTax[[#This Row],[RRC_TGT]] -> 0.58257919 | BK8: =PFS_SalesOverview_InTax[[#This Row],[UNITS_TGT]] -> 2173 | BL8: =_xlfn.XLOOKUP(PFS_SalesOverview_ExclTax[[#This Row],[DATE]],全店核心数据_bymonth[开始日期],全店核心数据_bymonth[jda日历.PayYear],"") -> BU26
